<?xml version='1.0'?>

<robot name="dd_bot" xmlns:xacro="http://www.ros.org/wiki/xacro">
  <!-- Import file with plugins for the camera, the lidar and the wheels (differential drive model for the odometry) -->
  <xacro:include filename="$(find my_robot)/urdf/ddbot_plugins.gazebo" />
  <!--<xacro:include filename="$(find my_robot)/urdf/colors.gazebo" />-->

  <link name="robot_footprint"></link>

  <joint name="robot_footprint_joint" type="fixed">
    <origin xyz="0 0 0" rpy="0 0 0" />
    <parent link="robot_footprint"/>
    <child link="chassis" />
  </joint>

  <link name='chassis'>
    <pose>0 0 0.2 0 0 0</pose>

    <inertial>
      <mass value="15.0"/>
      <origin xyz="0.0 0 0" rpy=" 0 0 0"/>
      <inertia
          ixx="0.1" ixy="0" ixz="0"
          iyy="0.1" iyz="0"
          izz="0.1"
      />
    </inertial>

    <collision name='chassis_collision'>
      <origin xyz="0 0 0" rpy=" 0 0 0"/> 
      <geometry>
        <box size="0.6 0.3 0.2"/>
      </geometry>
    </collision>

    <visual name='chassis_visual'>
      <origin xyz="0 0 0" rpy=" 0 0 0"/>
      <geometry>
        <box size="0.6 0.3 0.2"/>
      </geometry>
      <material name="greenish">
        <color rgba="0.0 0.8 0.5 1.0"/>
      </material>
    </visual>
    
  </link>

  <link name="caster">
        <visual>
            <geometry>
                <cylinder radius="0.05" length="0.1"/>
            </geometry>
            <material name="green">
                <color rgba="0.0 0.1 0.0 1"/>
            </material>
        </visual>
        <collision>
            <geometry>
                <cylinder radius="0.05" length="0.1"/>
            </geometry>
        </collision>
        <inertial>
            <mass value="0.1"/>
            <inertia ixx="0.00083" ixy="0" ixz="0" iyy="0.00083" iyz="0.0" izz="0.000167"/>
        </inertial>
  </link>

  <joint name="caster_joint" type="continuous">
       <axis xyz="0.0 0.0 1"/>
       <parent link="chassis"/>
       <child link="caster"/>
       <origin xyz="0.36 0.0 -0.05" rpy="0.0 0.0 0.0"/>
  </joint>

  <link name="front_wheel">
        <visual>
            <geometry>
                <cylinder radius="0.04" length="0.05"/>
            </geometry>
        </visual>
        <collision>
            <geometry>
                <cylinder radius="0.04" length="0.05"/>
            </geometry>
        </collision>
        <inertial>
            <mass value="0.1"/>
            <inertia ixx="5.1458e-5" ixy="0" ixz="0" iyy="5.1458e-5" iyz="0.0" izz="6.125e-5"/>
        </inertial>
  </link>

  <joint name="front_wheel_joint" type="continuous">
        <axis xyz="0.0 0.0 1"/>
        <parent link="caster"/>
        <child link="front_wheel"/>
        <origin xyz="0.0 0.0 -0.11" rpy="-1.5708 0.0 0.0"/>

  </joint>

  <link name="right_wheel">

    <inertial>
      <mass value="5.0"/>
      <origin xyz="0.0 0 0" rpy=" 0 1.5707 1.5707"/>
      <inertia
          ixx="0.1" ixy="0" ixz="0"
          iyy="0.1" iyz="0"
          izz="0.1"
      />
    </inertial>
        
    <visual>
      <origin xyz="0 0 0" rpy="0 1.5707 1.5707"/>
      <geometry>
        <cylinder radius="0.15" length="0.05"/>
      </geometry>
      <material name="black">
	  <color rgba="0.0 0.0 0.0 1.0"/>
      </material>
    </visual>

    <collision>
      <origin xyz="0 0 0" rpy="0 1.5707 1.5707"/>
      <geometry>
	 <cylinder radius="0.15" length="0.05"/>
      </geometry>
    </collision>

  </link>
  
  <link name="left_wheel">

    <inertial>
      <mass value="5.0"/>
      <origin xyz="0.0 0 0" rpy=" 0 1.5707 1.5707"/>
      <inertia
          ixx="0.1" ixy="0" ixz="0"
          iyy="0.1" iyz="0"
          izz="0.1"
      />
    </inertial>
    
    <collision>
      <origin xyz="0 0 0" rpy="0 1.5707 1.5707"/>
      <geometry>
	<cylinder radius="0.15" length="0.05"/>
      </geometry>
    </collision>
    
    <visual>
      <origin xyz="0 0 0" rpy="0 1.5707 1.5707"/>
      <geometry>
	<cylinder radius="0.15" length="0.05"/>
      </geometry>
      <material name="black">
	  <color rgba="0.0 0.0 0.0 1.0"/>
      </material>
    </visual>
    
  </link>
  
  <joint type="continuous" name="right_wheel_hinge">
    <origin xyz="-0.15 0.2 -0.05" rpy="0 0 0"/>
    <child link="right_wheel"/>
    <parent link="chassis"/>
    <axis xyz="0 1 0" rpy="0 0 0"/>
    <limit effort="10000" velocity="1000"/>
    <dynamics damping="1.0" friction="1.0"/>
  </joint>
  
  <joint type="continuous" name="left_wheel_hinge">
    <origin xyz="-0.15 -0.2 -0.05" rpy="0 0 0"/>
    <child link="left_wheel"/>
    <parent link="chassis"/>
    <axis xyz="0 1 0" rpy="0 0 0"/>
    <limit effort="10000" velocity="1000"/>
    <dynamics damping="1.0" friction="1.0"/>
  </joint>
   
</robot>
